<?xml version='1.0'?>
<!-- 
This model describes a ball and beam mechanism
-->

<sdf version='1.6'>
  <model name='BallBeam2D'>
    <link name='ground'>
      <pose frame=''>0 0 -5 0 0 0</pose>
      <inertial>
        <pose frame=''>0 0 0 0 0 0</pose>
        <mass>0</mass>
        <inertia>
          <ixx>0</ixx>
          <ixy>0</ixy>
          <ixz>0</ixz>
          <iyy>0</iyy>
          <iyz>0</iyz>
          <izz>0</izz>
        </inertia>
      </inertial>
      <collision name='ground_collision'>
        <pose frame=''>0 0 0 0 0 0</pose>
        <geometry>
          <box>
            <size>100.0 100.0 10.0</size>
          </box>
        </geometry>
      </collision>
      <visual name='ground_visual'>
        <pose frame=''>0 0 0 0 0 0</pose>
        <geometry>
          <box>
            <size>100.0 100.0 10.0</size>
          </box>
        </geometry>
        <material>
          <diffuse>0.54 0.54 0.54 0.9</diffuse>
        </material>
      </visual>
    </link>
    
    <link name='beam'>
      <inertial>
        <pose frame=''>0 0 1.89 0 0 0</pose>
        <mass>1</mass>
        <inertia>
          <ixx>1</ixx>
          <ixy>0</ixy>
          <ixz>0</ixz>
          <iyy>1</iyy>
          <iyz>0</iyz>
          <izz>1</izz>
        </inertia>
      </inertial>
      <visual name='beam_visual'>
        <pose frame=''>0 0 1.89 0 0 0</pose>
        <geometry>
          <box>
            <size>6 0 0.25</size>
          </box>
        </geometry>
        <material>
          <diffuse>1 0 0 1</diffuse>
        </material>
      </visual>
    </link>

    <link name='base'>
       <inertial>
        <pose frame=''>0 0 0 0 0 0</pose>
        <mass>10</mass>
        <inertia>
          <ixx>1</ixx>
          <ixy>0</ixy>
          <ixz>0</ixz>
          <iyy>1</iyy>
          <iyz>0</iyz>
          <izz>1</izz>
        </inertia>
      </inertial>
      <visual name='base_visual'>
        <pose frame=''>0 0.0 0.94 0 0 0</pose>
        <geometry>
          <cylinder>
            <radius>0.125</radius>
            <length>1.89</length>
          </cylinder>
        </geometry>
        <material>
          <diffuse>0 1 0 1</diffuse>
        </material>
      </visual>
    </link>
    
    <link name='ball'>
      <inertial>
        <pose frame=''>0 0 2.5 0 0 0</pose>
        <mass>0.1</mass>
        <inertia>
          <ixx>1</ixx>
          <ixy>0</ixy>
          <ixz>0</ixz>
          <iyy>1</iyy>
          <iyz>0</iyz>
          <izz>1</izz>
        </inertia>
      </inertial>
      <visual name='ball_visual'>
        <pose frame=''>0 0.0 2.5 0 0 0</pose>
        <geometry>
          <sphere>
            <radius>0.5</radius>
          </sphere>
        </geometry>
        <material>
          <diffuse>0 0 1 1</diffuse>
        </material>
      </visual>
    </link>
    
    <joint name="base_to_ground" type="fixed">
      <parent>ground</parent>
      <child>base</child>
    </joint>
    
    <joint name="base_to_beam" type="revolute">
      <parent>base</parent>
      <child>beam</child>
      <pose>0 0 1.89 0 0 0</pose>
      <axis>
        <xyz>0 -1 0</xyz>
        <limit>
          <effort>50.0</effort>
        </limit>
        <dynamics>
          <damping>0</damping>
          <friction>0</friction>
          <spring_reference>0</spring_reference>
          <spring_stiffness>0</spring_stiffness>
        </dynamics>
        <use_parent_model_frame>1</use_parent_model_frame>
      </axis>
    </joint>
    
    <joint name="beam_to_ball" type="prismatic">
      <parent>beam</parent>
      <child>ball</child>
      <axis>
        <xyz>1 0 0</xyz>
        <limit>
          <effort>0.0</effort>
          <upper>3.0</upper>
          <lower>-3.0</lower>
        </limit>
        <dynamics>
          <damping>0.2</damping>
          <friction>0</friction>
          <spring_reference>0</spring_reference>
          <spring_stiffness>0</spring_stiffness>
        </dynamics>
        <use_parent_model_frame>1</use_parent_model_frame>
      </axis>
    </joint>

  </model>
</sdf>
